<?xml version="1.0"?>
<robot name="four_wheel" xmlns:xacro="https://www.ros.org/wiki/xacro">

    <xacro:property name="pi_const" value="3.14150265" />
    
    <xacro:property name="length" value="1"/>
    <xacro:property name="height" value="0.3" />
    <xacro:property name="breadth" value="0.6" />
    
    <xacro:property name="radius" value="0.15" />
    <xacro:property name="d" value="0.1" />
    
    <xacro:property name="s1" value="${(height/2)+radius}" />
    <xacro:property name="s2" value="${2*radius}" />
    <xacro:property name="s3" value="${2*radius}" />
    <xacro:property name="s4" value="${breadth/2 + d/2}" />
    
    
    <!-- Densitites -->
    <xacro:property name="d1" value="2710.0" />
    <xacro:property name="d2" value="2710.0" />
    
    <!-- Mass  -->
    <xacro:property name="m1" value="${d1*length*breadth*height}" />
    <xacro:property name="m2" value="${d2*pi_const*radius*radius*d}" />
    
    <!-- Inertia   -->
    <!-- Box   -->
    <xacro:property name="Ix_box" value="${(1/12)*m1*(height*height+breadth*breadth)}"/>
    <xacro:property name="Iy_box" value="${(1/12)*m1*(length*length+height*height)}"/>
    <xacro:property name="Iz_box" value="${(1/12)*m1*(length*length+breadth*breadth)}"/>
    
    <xacro:property name="Iz_wheel" value="${0.5*m2*radius*radius}"/>
    <xacro:property name="I_wheel" value="${(1.0/12.0)*m2*(3.0*radius*radius+d*d)}"/>
    <xacro:include filename="$(find four_wheel_description)/model/parts/camera/camera.xacro" />
    
    <xacro:macro name="inertia_body">
        <inertial>
            <origin rpy="0.0 0.0 0.0" xyz="0 0 ${s1}"/>
            <mass value="${m1}"/>
            <inertia ixx="${Ix_box}" ixy="0.0" ixz="0.0" iyy="${Iy_box}" iyz="0.0" izz="${Iz_box}"/>
        </inertial>
    </xacro:macro>

    <xacro:macro name="inertia_wheel">
        <inertial>
            <origin xyz="0.0 0.0 0.0" rpy="1.570795 0.0 0.0"/>
            <mass value="${m2}"/>
            <inertia ixx="${I_wheel}" ixy="0.0" ixz="0.0" iyy="${I_wheel}" iyz="0.0" izz="${Iz_wheel}"/>
        </inertial>
    </xacro:macro>

    <xacro:include filename="$(find four_wheel_description)/model/four_rover_main.gazebo.xacro" />

    <!-- Links and joints -->
    <link name="base_footprint"> </link>
    <joint name="base_link_joint" type="fixed">
        <parent link="base_footprint"/>
        <child link="base_link"/>
    </joint>

    <link name="base_link">
        <visual>
            <origin xyz="0 0 ${s1}" rpy="0 0 0"/>
            <geometry>
                <box size="${length} ${breadth} ${height}"/>
            </geometry>
        </visual>

        <collision>
            <origin xyz="0 0 ${s1}" rpy="0 0 0"/>
            <geometry>
                <box size="${length} ${breadth} ${height}"/>
            </geometry>
        </collision>
        <xacro:inertia_body />
    </link>

    <joint name="d1_wheel_joint" type="continuous">
        <parent link="base_link"/>
        <child link="d1_wheel_link"/>
        <origin xyz="${-s2} ${-s4} ${radius}" rpy="0 0 0" /> 
        <axis xyz="0 1 0" />
        <limit effort="50000" velocity="10"/> 
        <dynamics damping="1.0" friction="1.0" />
    </joint>

    <link name="d1_wheel_link">
        <visual>
            <origin xyz="0 0.0 0.0" rpy="1.570795 0.0 0.0"/>
            <geometry>
                <cylinder radius="${radius}" length="${d}"/>
            </geometry>
        </visual>

        <collision>
            <origin xyz="0 0.0 0.0" rpy="1.570795 0.0 0.0"/>
            <geometry>
                <cylinder radius="${radius}" length="${d}"/>
            </geometry>
        </collision>

        <xacro:inertia_wheel />
    </link>

    <joint name="d2_wheel_joint" type="continuous">
        <parent link="base_link"/>
        <child link="d2_wheel_link"/>
        <origin xyz="${-s2} ${s4} ${radius}" rpy="0.0 0.0 0.0"/>
        <axis xyz="0 1 0"/>
        <limit effort="50000" velocity="10"/>
        <dynamics damping="1.0" friction="1.0" />
    </joint>

    <link name="d2_wheel_link">
        <visual>
            <origin xyz="0 0.0 0.0" rpy="1.570795 0.0 0.0"/>
            <geometry>
                <cylinder radius="${radius}" length="${d}"/>
            </geometry>
        </visual>

        <collision>
            <origin xyz="0 0.0 0.0" rpy="1.570795 0.0 0.0"/>
            <geometry>
                <cylinder radius="${radius}" length="${d}"/>
            </geometry>
        </collision>
        <xacro:inertia_wheel />
    </link>


    <!-- Caster wheels  -->
     <link name="caster1_link">
        <visual>
            <origin xyz="0 0 0" rpy="1.570795 0 0"/>
            <geometry>
                <cylinder radius="${radius}" length="${d}"/>
            </geometry>
        </visual>

        <collision>
            <origin xyz="0 0 0" rpy="1.570795 0 0"/>
            <geometry>
                <cylinder radius="${radius}" length="${d}"/>
            </geometry>
        </collision>
        <xacro:inertia_wheel />
    </link>

    <joint name="caster1_joint" type="fixed">
        <parent link="base_link"/>
        <child link="caster1_link"/>
        <origin xyz="${s2} ${-s4} ${radius}" rpy="0 0 0" />
        <axis xyz="0 1 0"/>
        <limit effort="50000" velocity="10"/>
        <dynamics damping="1.0" friction="1.0" />
    </joint>


    <link name="caster2_link">
        <visual>
            <origin xyz="0 0 0" rpy="1.570795 0 0"/>
            <geometry>
                <cylinder radius="${radius}" length="${d}"/>
            </geometry>
        </visual>

        <collision>
            <origin xyz="0 0 0" rpy="1.570795 0 0"/>
            <geometry>
                <cylinder radius="${radius}" length="${d}"/>
            </geometry>
        </collision>
        <xacro:inertia_wheel />
    </link>

    <joint name="caster2_joint" type="fixed">
        <parent link="base_link"/>
        <child link="caster2_link"/>
        <origin xyz="${s2} ${s4} ${radius}" rpy="0 0 0" />
        <axis xyz="0 1 0"/>
        <limit effort="50000" velocity="10"/>
        <dynamics damping="1.0" friction="1.0" />
    </joint>


</robot>